Workbook

Sheet 1_2025_예산요약
A1: 2025 졸업준비위원회 예산 요약
A2: 출처: 2025_졸업준비위원회_팀 별 예산안.xlsx (총무 작성, 최종 배정표) · 전시 2025.11.21–23
A4: ① 재원(수입)
A5: 재원 | B5: 금액(원) | C5: 산출 근거
A6: 학생회비 | B6: 7200000 | C6: 인당 60,000원 × 120명 (10/15 확정)
A7: 전시지원금 | B7: 3200000 | C7: 학교·학과 지원 · 전시 설치·가벽·자재 등 사용처 제한
A8: 성과전시지원금 | B8: 2500000 | C8: 학교·학과 지원 · 하드웨어(PC 렌탈)에 전액 배정
A9: 총 재원 | B9: =SUM(B6:B8)
A11: ② 팀별 배정 (예산안 구분별)
A12: 팀 | B12: 학생회비 | C12: 전시지원금 | D12: 성과전시지원금 | E12: 팀별 합계 | F12: 비중 | G12: 비고
A13: 브랜딩팀 | B13: 1200000 | C13: 700000 | D13: 0 | E13: =SUM(B13:D13) | F13: =IFERROR(E13/$E$19,0) | G13: 홍보팀 포함
A14: 전시팀 | B14: 3760000 | C14: 1781200 | D14: 0 | E14: =SUM(B14:D14) | F14: =IFERROR(E14/$E$19,0) | G14: 가벽·테이블 렌탈 등 최대 배정
A15: 오프닝팀 | B15: 1200000 | C15: 400000 | D15: 0 | E15: =SUM(B15:D15) | F15: =IFERROR(E15/$E$19,0) | G15: 졸업선물(타올) 포함
A16: 하드웨어팀 | B16: 100000 | C16: 0 | D16: 2500000 | E16: =SUM(B16:D16) | F16: =IFERROR(E16/$E$19,0) | G16: iMac 등 PC 렌탈
A17: 영상팀 | B17: 300000 | C17: 0 | D17: 0 | E17: =SUM(B17:D17) | F17: =IFERROR(E17/$E$19,0) | G17: DIMO 동아리 · 세부 예산안 파일 없음
A18: 본부 | B18: 440000 | C18: 118800 | D18: 0 | E18: =SUM(B18:D18) | F18: =IFERROR(E18/$E$19,0) | G18: 전시지원금 118,800 = 웹사이트 연장
A19: 배정 합계 | B19: =SUM(B13:B18) | C19: =SUM(C13:C18) | D19: =SUM(D13:D18) | E19: =SUM(E13:E18) | F19: =IFERROR(E19/$E$19,0)
A20: 예비비 (재원 − 배정) | B20: =B6-B19 | C20: =B7-C19 | D20: =B8-D19 | E20: =B9-E19
A22: ③ 팀별 배정 vs 세부 예산안(2차) 비교
A23: 팀 | B23: 배정액 | C23: 세부 예산안 합계 (졸준위 예산분) | D23: 차이 (배정 − 예산안) | E23: 시제품제작비로 돌린 금액 (졸준위 예산 외)
A24: 브랜딩팀 | B24: =E13 | C24: =SUMIFS('2_2025_항목별예산안'!$E:$E,'2_2025_항목별예산안'!$A:$A,A24,'2_2025_항목별예산안'!$B:$B,"졸준위 예산") | D24: =B24-C24 | E24: =SUMIFS('2_2025_항목별예산안'!$E:$E,'2_2025_항목별예산안'!$A:$A,A24,'2_2025_항목별예산안'!$B:$B,"시제품제작비")
A25: 전시팀 | B25: =E14 | C25: =SUMIFS('2_2025_항목별예산안'!$E:$E,'2_2025_항목별예산안'!$A:$A,A25,'2_2025_항목별예산안'!$B:$B,"졸준위 예산") | D25: =B25-C25 | E25: =SUMIFS('2_2025_항목별예산안'!$E:$E,'2_2025_항목별예산안'!$A:$A,A25,'2_2025_항목별예산안'!$B:$B,"시제품제작비")
A26: 오프닝팀 | B26: =E15 | C26: =SUMIFS('2_2025_항목별예산안'!$E:$E,'2_2025_항목별예산안'!$A:$A,A26,'2_2025_항목별예산안'!$B:$B,"졸준위 예산") | D26: =B26-C26 | E26: =SUMIFS('2_2025_항목별예산안'!$E:$E,'2_2025_항목별예산안'!$A:$A,A26,'2_2025_항목별예산안'!$B:$B,"시제품제작비")
A27: 하드웨어팀 | B27: =E16 | C27: =SUMIFS('2_2025_항목별예산안'!$E:$E,'2_2025_항목별예산안'!$A:$A,A27,'2_2025_항목별예산안'!$B:$B,"졸준위 예산") | D27: =B27-C27 | E27: =SUMIFS('2_2025_항목별예산안'!$E:$E,'2_2025_항목별예산안'!$A:$A,A27,'2_2025_항목별예산안'!$B:$B,"시제품제작비")
A28: 영상팀 | B28: =E17 | C28: =SUMIFS('2_2025_항목별예산안'!$E:$E,'2_2025_항목별예산안'!$A:$A,A28,'2_2025_항목별예산안'!$B:$B,"졸준위 예산") | D28: =B28-C28 | E28: =SUMIFS('2_2025_항목별예산안'!$E:$E,'2_2025_항목별예산안'!$A:$A,A28,'2_2025_항목별예산안'!$B:$B,"시제품제작비")
A29: 본부 | B29: =E18 | C29: =SUMIFS('2_2025_항목별예산안'!$E:$E,'2_2025_항목별예산안'!$A:$A,A29,'2_2025_항목별예산안'!$B:$B,"졸준위 예산") | D29: =B29-C29 | E29: =SUMIFS('2_2025_항목별예산안'!$E:$E,'2_2025_항목별예산안'!$A:$A,A29,'2_2025_항목별예산안'!$B:$B,"시제품제작비")
A30: 합계 | B30: =SUM(B24:B29) | C30: =SUM(C24:C29) | D30: =SUM(D24:D29) | E30: =SUM(E24:E29)
A32: ※ 참고
A33: · 2025년 실제 지출 장부(2025_졸업준비위원회_수입지출내역.xlsx)는 폴더에 원본이 없고 잠금파일(~$)만 남아 있습니다. 팀별 예산안의 '2025_예산내역' 시트도 빈 양식 상태입니다.
A34: · 따라서 2025년은 '배정액 + 팀별 2차 예산안(계획)' 기준이며, 실제 결제 금액·영수증은 노션 졸준위 페이지 또는 전임 총무에게 확인이 필요합니다.
A35: · 항목별 실제 집행 내역이 남아 있는 가장 최근 자료는 2024년입니다 → 시트 '3_2024_실집행내역' 참고.
A36: · 영상팀·하드웨어팀은 세부 예산안 파일이 없어 ③의 차이가 크게 나옵니다 (하드웨어 렌탈 견적은 시트 2 하단 참고).
A37: · 파란 글씨 = 원본 파일에서 옮겨 적은 값, 검정 글씨 = 수식.

Sheet 2_2025_항목별예산안
A1: 2025 팀별 항목별 예산안 (2차 · 최종 제출본)
A2: 출처: 2차_예산안_브랜딩팀_1019 / 오프닝팀_1021 / 전시팀_1021, 2025_졸업준비위원회_팀 별 예산안.xlsx · 계획 금액이며 실결제액과 다를 수 있음
A4: 팀 | B4: 재원 구분 | C4: 분류 | D4: 항목 | E4: 금액(원) | F4: 수량 | G4: 구매처 | H4: 용도·비고 | I4: 출처 파일
A5: 브랜딩팀 | B5: 졸준위 예산 | C5: 회의비 | D5: 회의비 (6인) | E5: 120000 | F5: 6명 | I5: 2차_예산안_브랜딩팀_1019
A6: 브랜딩팀 | B6: 졸준위 예산 | C6: 장비 | D6: 에어마우스 | E6: 60000 | F6: 1 | G6: 쿠팡 | H6: 참여형 인터랙션 | I6: 2차_예산안_브랜딩팀_1019
A7: 브랜딩팀 | B7: 졸준위 예산 | C7: 인쇄·홍보물 | D7: 세로형 배너 60×180cm | E7: 135200 | F7: 4 | G7: 비즈하우스 | H7: 공간활용 및 브랜드 아이덴티티 | I7: 2차_예산안_브랜딩팀_1019
A8: 브랜딩팀 | B8: 졸준위 예산 | C8: 인쇄·홍보물 | D8: 대형 종이포스터 A1 (별색, 버전1) | E8: 330000 | F8: 50 | G8: 제이엠기획 | H8: 전시장 내부 부착·홍보 | I8: 2차_예산안_브랜딩팀_1019
A9: 브랜딩팀 | B9: 졸준위 예산 | C9: 인쇄·홍보물 | D9: 대형 종이포스터 A1 (별색, 버전2) | E9: 330000 | F9: 50 | G9: 제이엠기획 | I9: 2차_예산안_브랜딩팀_1019
A10: 브랜딩팀 | B10: 졸준위 예산 | C10: 공간 연출 | D10: 바닥 실내 PU 1000×1000cm | E10: 300000 | F10: 10 | G10: 레드프린팅 | H10: 바닥 랩핑 | I10: 2차_예산안_브랜딩팀_1019
A11: 브랜딩팀 | B11: 졸준위 예산 | C11: 인쇄·홍보물 | D11: 대형 현수막 700×320 | E11: 136300 | F11: 1 | G11: 비즈하우스 | H11: 화이트보드 가림 | I11: 2차_예산안_브랜딩팀_1019
A12: 브랜딩팀 | B12: 졸준위 예산 | C12: 공간 연출 | D12: 시트지 스티커 | E12: 99000 | F12: 9 | G12: 비즈하우스 | H12: UT 스튜디오 창문 부착 | I12: 2차_예산안_브랜딩팀_1019
A13: 브랜딩팀 | B13: 졸준위 예산 | C13: 인쇄·홍보물 | D13: 포인트 심플 입간판 | E13: 59100 | F13: 1 | G13: 비즈하우스 | H13: 즉석 사진 입간판 | I13: 2차_예산안_브랜딩팀_1019
A14: 브랜딩팀 | B14: 졸준위 예산 | C14: 인쇄·홍보물 | D14: 미니 배너 | E14: 15500 | F14: 5 | G14: 비즈하우스 | H14: 테이블 위 설명 | I14: 2차_예산안_브랜딩팀_1019
A15: 브랜딩팀 | B15: 졸준위 예산 | C15: 장비 | D15: 즉석 사진기 대여(3일) | E15: 320000 | F15: 1 | G15: 더블에이치솔루션 | H15: 즉석 사진 출력 | I15: 2차_예산안_브랜딩팀_1019
A16: 브랜딩팀 | B16: 시제품제작비 | C16: 인쇄·홍보물 | D16: 3D 리플렛 | E16: 221000 | F16: 300 | G16: 비즈하우스 | H16: 엘리베이터 앞 배부 | I16: 2차_예산안_브랜딩팀_1019
A17: 브랜딩팀 | B17: 시제품제작비 | C17: 인쇄·홍보물 | D17: 프리미엄 명함 | E17: 17160 | F17: 600 | G17: 레드프린팅 | H17: 테이블 위 배치 | I17: 2차_예산안_브랜딩팀_1019
A18: 브랜딩팀 | B18: 시제품제작비 | C18: 굿즈·이벤트 | D18: 싱글 규격 스티커 | E18: 5600 | F18: 300 | G18: 비즈하우스 | I18: 2차_예산안_브랜딩팀_1019
A19: 브랜딩팀 | B19: 시제품제작비 | C19: 굿즈·이벤트 | D19: 고무인 20 무지 스탬프 | E19: 4070 | F19: 1 | G19: 레드프린팅 | I19: 2차_예산안_브랜딩팀_1019
A20: 브랜딩팀 | B20: 시제품제작비 | C20: 굿즈·이벤트 | D20: 고무인 자유형 무지 스탬프 | E20: 4840 | F20: 1 | G20: 레드프린팅 | I20: 2차_예산안_브랜딩팀_1019
A21: 브랜딩팀 | B21: 시제품제작비 | C21: 굿즈·이벤트 | D21: 마스킹 테이프 | E21: 4620 | F21: 2 | G21: 레드프린팅 | I21: 2차_예산안_브랜딩팀_1019
A22: 브랜딩팀 | B22: 시제품제작비 | C22: 굿즈·이벤트 | D22: 디지털 프린팅 에코백 | E22: 49800 | F22: 3 | G22: 비즈하우스 | H22: 이벤트 상품 | I22: 2차_예산안_브랜딩팀_1019
A23: 브랜딩팀 | B23: 시제품제작비 | C23: 굿즈·이벤트 | D23: 더블 파스텔 텀블러 | E23: 28290 | F23: 3 | G23: 비즈하우스 | H23: 이벤트 상품 | I23: 2차_예산안_브랜딩팀_1019
A24: 브랜딩팀 | B24: 시제품제작비 | C24: 굿즈·이벤트 | D24: WB아이오펜 1.0mm | E24: 43000 | F24: 100 | G24: 비즈하우스 | I24: 2차_예산안_브랜딩팀_1019
A25: 브랜딩팀 | B25: 시제품제작비 | C25: 굿즈·이벤트 | D25: 아크릴 명찰 | E25: 23100 | F25: 6 | G25: 레드프린팅 | H25: 스태프 부착 | I25: 2차_예산안_브랜딩팀_1019
A26: 브랜딩팀 | B26: 시제품제작비 | C26: 인쇄·홍보물 | D26: 대형 현수막 300×320 | E26: 115200 | F26: 2 | G26: 비즈하우스 | H26: 즉석 사진 배경·공간분리 | I26: 2차_예산안_브랜딩팀_1019
A27: 브랜딩팀 | B27: 시제품제작비 | C27: 인쇄·홍보물 | D27: 대형 현수막 500×190 | E27: 57000 | F27: 1 | G27: 비즈하우스 | H27: 브랜드 아이덴티티 | I27: 2차_예산안_브랜딩팀_1019
A28: 브랜딩팀 | B28: 시제품제작비 | C28: 소모품 | D28: 기타 소모품(가위·비닐·접착제) | E28: 10000 | F28: - | G28: 다이소 | I28: 2차_예산안_브랜딩팀_1019
A29: 오프닝팀 | B29: 졸준위 예산 | C29: 장식 | D29: 풍선 부는 기계 | E29: 48400 | F29: 2개 | G29: 쿠팡 | H29: 다목적홀 내외부 장식 | I29: 2차_예산안_오프닝팀_1021
A30: 오프닝팀 | B30: 졸준위 예산 | C30: 장식 | D30: 원형 풍선(실버) | E30: 5500 | F30: 50개 | G30: 쿠팡 | H30: 다목적홀 내부 장식 | I30: 2차_예산안_오프닝팀_1021
A31: 오프닝팀 | B31: 졸준위 예산 | C31: 장식 | D31: 원형 풍선(화이트) | E31: 7080 | F31: 50개 | G31: 쿠팡 | H31: 다목적홀 내부 장식 | I31: 2차_예산안_오프닝팀_1021
A32: 오프닝팀 | B32: 졸준위 예산 | C32: 장식 | D32: 긴 풍선(실버) | E32: 6900 | F32: 100개 | G32: 쿠팡 | H32: 다목적홀 외부 장식 | I32: 2차_예산안_오프닝팀_1021
A33: 오프닝팀 | B33: 졸준위 예산 | C33: 장식 | D33: 긴 풍선(화이트) | E33: 7540 | F33: 100개 | G33: 쿠팡 | H33: 다목적홀 외부 장식 | I33: 2차_예산안_오프닝팀_1021
A34: 오프닝팀 | B34: 졸준위 예산 | C34: 장식 | D34: 흰색 수술 1000×2000mm | E34: 8800 | F34: 3개 | G34: 쿠팡 | H34: 다목적홀 외부 장식 | I34: 2차_예산안_오프닝팀_1021
A35: 오프닝팀 | B35: 졸준위 예산 | C35: 상품 | D35: 배달의민족 30,000원 금액권 | E35: 180000 | F35: 6개 | G35: 카카오톡 선물하기 | H35: 2부 레크레이션(카훗) 상품 | I35: 2차_예산안_오프닝팀_1021
A36: 오프닝팀 | B36: 졸준위 예산 | C36: 졸업선물 | D36: 자수 타올 주문제작(블랙) | E36: 819000 | F36: 130개 | G36: 네이버 스마트스토어(송월) | H36: 졸업예정자·전임 교수님 기념 선물 | I36: 2차_예산안_오프닝팀_1021
A37: 오프닝팀 | B37: 졸준위 예산 | C37: 졸업선물 | D37: 선물 상자(블랙) | E37: 95200 | F37: 136개 | G37: 쿠팡 | H37: 졸업선물 포장 | I37: 2차_예산안_오프닝팀_1021
A38: 오프닝팀 | B38: 졸준위 예산 | C38: 졸업선물 | D38: 투명 카드택 | E38: 30950 | F38: 132개 | G38: 퍼블로그 | H38: 졸업선물 포장 | I38: 2차_예산안_오프닝팀_1021
A39: 오프닝팀 | B39: 졸준위 예산 | C39: 졸업선물 | D39: 포장용 리본끈(블루) 6mm | E39: 29950 | F39: 5개 | G39: 쿠팡 | H39: 졸업선물 포장 | I39: 2차_예산안_오프닝팀_1021
A40: 오프닝팀 | B40: 졸준위 예산 | C40: 졸업선물 | D40: 포장용 디자인 종이 A4 | E40: 34550 | F40: 65세트 | G40: 퍼블로그 | H40: 졸업선물 포장 | I40: 2차_예산안_오프닝팀_1021
... A42: 오프닝팀 | B42: 졸준위 예산 | C42: 배송비 | D42: 배송비 전체 | E42: 100000 | F42: - | G42: 쿠팡 | H42: 온라인 주문 배송비 | I42: 2차_예산안_오프닝팀_1021
...

Sheet 3_2024_실집행내역
A1: 2024 졸업준비위원회 실제 지출 내역 (항목별)
A2: 출처: 2024 졸업준비위원회_수입지출내역.xlsx · 결제/송금 완료 기준 · 실제 사용 기록이 남아 있는 최신 자료
A4: 팀 | B4: 내역 | C4: 재원 | D4: 예산액(원) | E4: 실사용액(원) | F4: 반환·잔액(원) | G4: 사용처 | H4: 실 결제일 | I4: 상태 | J4: 비고
A5: 본부 | B5: 회의비 (졸전 설치 저녁 식사) | C5: 학생회비 | D5: 60000 | E5: 26000 | F5: =D5-E5 | J5: 13,000×2 (11/20) · 학회장 계좌
A6: 본부 | B6: 졸업전시 사이트 도메인 연장 | C6: 전시지원금 | D6: 118800 | E6: 118800 | F6: =D6-E6 | G6: 카페24 | H6: 45604 | I6: 구매완료
A7: 본부 | B7: [예비비] 부스 설치 인원 식사 | C7: 학생회비 | D7: 143000 | E7: 143000 | F7: =D7-E7 | H7: 45615 | I7: 송금완료 | J7: 학회장 계좌
A8: 본부 | B8: [예비비] 오프닝팀 택시비 | C8: 학생회비 | D8: 15800 | E8: 15800 | F8: =D8-E8 | G8: 택시 | H8: 45618 | I8: 송금완료 | J8: 케이크 이동
A9: 본부 | B9: [예비비] 물 구매 (15묶음) | C9: 학생회비 | D9: 127940 | E9: 127940 | F9: =D9-E9 | G9: 쿠팡 | H9: 45616 | I9: 구매완료
A10: 본부 | B10: [예비비] 전시팀 한가람 구매 | C10: 학생회비 | D10: 23600 | E10: 23600 | F10: =D10-E10 | G10: 한가람 | H10: 45617 | I10: 송금완료 | J10: 전시팀장 계좌
A11: 본부 | B11: [예비비] 전시팀 택시비 | C11: 학생회비 | D11: 16300 | E11: 16300 | F11: =D11-E11 | G11: 택시 | H11: 45616 | I11: 송금완료
A12: 홍보팀 | B12: 회의비 (9명) | C12: 학생회비 | D12: 270000 | E12: 270000 | F12: =D12-E12 | H12: 45602 | I12: 송금완료 | J12: 홍보팀장 계좌
A13: 홍보팀 | B13: 화이트 B2 포스터 (별색) 50매 | C13: 전시지원금 | D13: 330000 | E13: 330000 | F13: =D13-E13 | G13: 제이엠기획 | H13: 45611 | I13: 구매완료
A14: 홍보팀 | B14: 블랙 B2 포스터 (별색) 50매 | C14: 전시지원금 | D14: 330000 | E14: 330000 | F14: =D14-E14 | G14: 제이엠기획 | H14: 45611 | I14: 구매완료
A15: 홍보팀 | B15: 대형현수막 A 720×514cm | C15: 전시지원금 | D15: 33000 | E15: 33000 | F15: =D15-E15 | H15: 45611 | I15: 구매완료
A16: 홍보팀 | B16: 대형현수막 B 420×300cm | C16: 전시지원금 | D16: 33000 | E16: 33000 | F16: =D16-E16 | H16: 45611 | I16: 구매완료
A17: 홍보팀 | B17: 케이블타이 | C17: 전시지원금 | D17: 7900 | E17: 7900 | F17: =D17-E17 | G17: 쿠팡 | I17: 구매완료
A18: 홍보팀 | B18: 메모지 | C18: 전시지원금 | D18: 22400 | E18: 22400 | F18: =D18-E18 | G18: 쿠팡 | I18: 구매완료
A19: 홍보팀 | B19: 볼펜 | C19: 전시지원금 | D19: 9400 | E19: 9400 | F19: =D19-E19 | G19: 쿠팡 | I19: 구매완료
A20: 홍보팀 | B20: 배부용 비닐 봉투 | C20: 전시지원금 | D20: 42100 | E20: 42100 | F20: =D20-E20 | G20: 쿠팡 | I20: 구매완료
A21: 홍보팀 | B21: 형광 시트지 | C21: 전시지원금 | D21: 11000 | E21: 11000 | F21: =D21-E21 | G21: 쿠팡 | I21: 구매완료
A22: 홍보팀 | B22: 형광 스티커 롤 | C22: 전시지원금 | D22: 7480 | E22: 7480 | F22: =D22-E22 | G22: 쿠팡 | I22: 구매완료
A23: 홍보팀 | B23: 형광 면 테이프 | C23: 전시지원금 | D23: 14100 | E23: 14100 | F23: =D23-E23 | G23: 쿠팡 | I23: 구매완료
A24: 홍보팀 | B24: 폼보드 | C24: 전시지원금 | D24: 22650 | E24: 22650 | F24: =D24-E24 | G24: 쿠팡 | I24: 구매완료
A25: 홍보팀 | B25: 배송비 | C25: 전시지원금 | D25: 8600 | E25: 8600 | F25: =D25-E25 | G25: 쿠팡 | I25: 구매완료
A26: 전시팀 | B26: 회의비 (12명) | C26: 학생회비 | D26: 360000 | E26: 360000 | F26: =D26-E26 | H26: 45603 | I26: 송금완료 | J26: 전시팀장 계좌
A27: 전시팀 | B27: 파티션 대여 (32개) | C27: 학생회비 | D27: 1364000 | E27: 1364000 | F27: =D27-E27 | G27: 강남렌탈 | H27: 45616 | I27: 송금완료 | J27: 전시팀장 계좌
A28: 전시팀 | B28: 파티션 가림 천 (실 수량 60장) | C28: 학생회비 | D28: 789600 | E28: 789600 | F28: =D28-E28 | G28: 원단닷컴 | H28: 45644 | I28: 구매완료
A29: 전시팀 | B29: 테이블+테이블보 대여 (17개) | C29: 전시지원금 | D29: 638000 | E29: 638000 | F29: =D29-E29 | G29: 렌탈프리 | H29: 45620 | I29: 구매완료
A30: 전시팀 | B30: 천 고정용 양면 테이프 (13개) | C30: 성과전시지원금 | D30: 150300 | E30: 150300 | F30: =D30-E30 | G30: 일상공감 | H30: 45602 | I30: 구매완료
A31: 전시팀 | B31: 스티커 제거제 (16개) | C31: 전시지원금 | D31: 59440 | E31: 59440 | F31: =D31-E31 | G31: 쿠팡 | H31: 45604 | I31: 구매완료
A32: 전시팀 | B32: 스크래퍼 (6개) | C32: 전시지원금 | D32: 15900 | E32: 15900 | F32: =D32-E32 | G32: 쿠팡 | H32: 45604 | I32: 구매완료
A33: 전시팀 | B33: 목장갑 (10개) | C33: 전시지원금 | D33: 4000 | E33: 4000 | F33: =D33-E33 | G33: 쿠팡 | H33: 45604 | I33: 구매완료
A34: 전시팀 | B34: 스팀다리미 (3개) | C34: 학생회비 | D34: 77970 | E34: 77970 | F34: =D34-E34 | G34: 쿠팡 | H34: 45604 | I34: 구매완료 | J34: 전시지원금으로 구매 불가 품목
A35: 전시팀 | B35: 마스킹 테이프 (4개) | C35: 전시지원금 | D35: 8900 | E35: 8900 | F35: =D35-E35 | G35: 쿠팡 | H35: 45604 | I35: 구매완료
A36: 오프닝팀 | B36: 회의비 (8명) | C36: 학생회비 | D36: 240000 | E36: 100900 | F36: =D36-E36 | H36: 45601 | I36: 송금완료 | J36: 남은 139,100원 11/26 반환
A37: 오프닝팀 | B37: 케이크 | C37: 학생회비 | D37: 122000 | E37: 122000 | F37: =D37-E37 | G37: 클로버 케이크 | H37: 45601 | I37: 송금완료
A38: 오프닝팀 | B38: 헬륨풍선 (투명·핑크앤블루) | C38: 학생회비 | D38: 170500 | E38: 170500 | F38: =D38-E38 | G38: 파티하우스 | H38: 45604 | I38: 구매완료
A39: 오프닝팀 | B39: 라운드 풍선 펄 화이트 (50개) | C39: 전시지원금 | D39: 6400 | E39: 6400 | F39: =D39-E39 | G39: 쿠팡 | H39: 45604 | I39: 구매완료
A40: 오프닝팀 | B40: 인조 넝쿨 조화 | C40: 전시지원금 | D40: 11000 | E40: 11000 | F40: =D40-E40 | G40: 쿠팡 | H40: 45604 | I40: 구매완료
A41: 오프닝팀 | B41: 자이언트 조화 (대형 꽃) | C41: 전시지원금 | D41: 32400 | E41: 32400 | F41: =D41-E41 | G41: 쿠팡 | H41: 45604 | I41: 구매완료
...

Sheet 4_연도별비교
A1: 연도별 졸준위 예산 비교
A2: 출처: 2025_졸준위_분석본.html(2023), 각 연도 예산안 파일(2024·2025)
A4: 연도 | B4: 학생회비 | C4: 전시지원금 | D4: 성과전시지원금 | E4: 기타 | F4: 총 재원 | G4: 인당 회비 | H4: 졸준위 인원
A5: 2023 | B5: 6510000 | C5: 2600000 | D5: 1381200 | E5: 1860000 | F5: =SUM(B5:E5) | G5: 70000 | H5: 48
A6: 2024 | B6: 4635000 | C6: 2950000 | D6: 2500000 | E6: 0 | F6: =SUM(B6:E6) | G6: 45000 | H6: 43
A7: 2025 | B7: 7200000 | C7: 3200000 | D7: 2500000 | E7: 0 | F7: =SUM(B7:E7) | G7: 60000 | H7: 51
A8: ※ 2023 기타 = 시제품 지원 1,860,000원. 2025 졸준위 인원은 예산안 기준 51명(본부 2 포함).
A10: 팀별 비교: 2024 실사용 vs 2025 배정
A11: 팀 | B11: 2024 실사용 | C11: 2025 배정 | D11: 증감 | E11: 증감률 | F11: 비고
A12: 브랜딩·홍보 | B12: =INDEX('3_2024_실집행내역'!$E$60:$E$65,MATCH("홍보팀",'3_2024_실집행내역'!$A$60:$A$65,0)) | C12: =INDEX('1_2025_예산요약'!$E$13:$E$18,MATCH("브랜딩팀",'1_2025_예산요약'!$A$13:$A$18,0)) | D12: =C12-B12 | E12: =IFERROR(D12/B12,0) | F12: 2024 홍보팀 → 2025 브랜딩팀(홍보 포함)
A13: 전시팀 | B13: =INDEX('3_2024_실집행내역'!$E$60:$E$65,MATCH("전시팀",'3_2024_실집행내역'!$A$60:$A$65,0)) | C13: =INDEX('1_2025_예산요약'!$E$13:$E$18,MATCH("전시팀",'1_2025_예산요약'!$A$13:$A$18,0)) | D13: =C13-B13 | E13: =IFERROR(D13/B13,0) | F13: 2025 가벽을 라이트너 전시가벽(440만)으로 교체
A14: 오프닝팀 | B14: =INDEX('3_2024_실집행내역'!$E$60:$E$65,MATCH("오프닝팀",'3_2024_실집행내역'!$A$60:$A$65,0)) | C14: =INDEX('1_2025_예산요약'!$E$13:$E$18,MATCH("오프닝팀",'1_2025_예산요약'!$A$13:$A$18,0)) | D14: =C14-B14 | E14: =IFERROR(D14/B14,0)
A15: 하드웨어팀 | B15: =INDEX('3_2024_실집행내역'!$E$60:$E$65,MATCH("하드웨어팀",'3_2024_실집행내역'!$A$60:$A$65,0)) | C15: =INDEX('1_2025_예산요약'!$E$13:$E$18,MATCH("하드웨어팀",'1_2025_예산요약'!$A$13:$A$18,0)) | D15: =C15-B15 | E15: =IFERROR(D15/B15,0)
A16: 영상팀 | B16: =INDEX('3_2024_실집행내역'!$E$60:$E$65,MATCH("영상팀",'3_2024_실집행내역'!$A$60:$A$65,0)) | C16: =INDEX('1_2025_예산요약'!$E$13:$E$18,MATCH("영상팀",'1_2025_예산요약'!$A$13:$A$18,0)) | D16: =C16-B16 | E16: =IFERROR(D16/B16,0)
A17: 본부 | B17: =INDEX('3_2024_실집행내역'!$E$60:$E$65,MATCH("본부",'3_2024_실집행내역'!$A$60:$A$65,0)) | C17: =INDEX('1_2025_예산요약'!$E$13:$E$18,MATCH("본부",'1_2025_예산요약'!$A$13:$A$18,0)) | D17: =C17-B17 | E17: =IFERROR(D17/B17,0)
A18: 합계 | B18: =SUM(B12:B17) | C18: =SUM(C12:C17) | D18: =SUM(D12:D17) | E18: =IFERROR(D18/B18,0)
A19: ※ 초록 글씨 = 다른 시트에서 가져온 값.
